execute at @e[tag=only] run setblock ~ ~-1 ~ oak_planks destroy
execute at @e[tag=only] run setblock ~1 ~-1 ~ oak_planks destroy
execute at @e[tag=only] run setblock ~-1 ~-1 ~ oak_planks destroy
execute at @e[tag=only] run setblock ~ ~-1 ~1 oak_planks destroy
execute at @e[tag=only] run setblock ~ ~-1 ~-1 oak_planks destroy
execute at @e[tag=only] run setblock ~1 ~-1 ~1 oak_planks destroy
execute at @e[tag=only] run setblock ~-1 ~-1 ~1 oak_planks destroy
execute at @e[tag=only] run setblock ~-1 ~-1 ~-1 oak_planks destroy
execute at @e[tag=only] run setblock ~-1 ~-1 ~1 oak_planks destroy
execute at @e[tag=only] run setblock ~1 ~-1 ~-1 oak_planks destroy
execute at @e[tag=only] run setblock ~2 ~-1 ~-2 minecraft:oak_log[ axis=y] destroy
execute at @e[tag=only] run setblock ~-2 ~-1 ~2 minecraft:oak_log[ axis=y] destroy
execute at @e[tag=only] run setblock ~2 ~-1 ~2 minecraft:oak_log[ axis=y] destroy
execute at @e[tag=only] run setblock ~-2 ~-1 ~-2 minecraft:oak_log[ axis=y] destroy
execute at @e[tag=only] run setblock ~ ~-1 ~-2 minecraft:oak_wood[axis=y] destroy
execute at @e[tag=only] run setblock ~1 ~-1 ~-2 minecraft:oak_wood[axis=y] destroy
execute at @e[tag=only] run setblock ~-1 ~-1 ~-2 minecraft:oak_wood[axis=y] destroy
execute at @e[tag=only] run setblock ~ ~-1 ~2 minecraft:oak_wood[axis=y] destroy
execute at @e[tag=only] run setblock ~1 ~-1 ~2 minecraft:oak_wood[axis=y] destroy
execute at @e[tag=only] run setblock ~-1 ~-1 ~2 minecraft:oak_wood[axis=y] destroy
execute at @e[tag=only] run setblock ~2 ~-1 ~ minecraft:oak_wood[axis=x] destroy
execute at @e[tag=only] run setblock ~2 ~-1 ~1 minecraft:oak_wood[axis=x] destroy
execute at @e[tag=only] run setblock ~2 ~-1 ~-1 minecraft:oak_wood[axis=x] destroy
execute at @e[tag=only] run setblock ~-2 ~-1 ~ minecraft:oak_wood[axis=x] destroy
execute at @e[tag=only] run setblock ~-2 ~-1 ~1 minecraft:oak_wood[axis=x] destroy
execute at @e[tag=only] run setblock ~-2 ~-1 ~-1 minecraft:oak_wood[axis=x] destroy

execute at @e[tag=only] run setblock ~-2 ~ ~-2 minecraft:oak_log[ axis=y] destroy
execute at @e[tag=only] run setblock ~-2 ~1 ~-2 minecraft:oak_log[ axis=y] destroy
execute at @e[tag=only] run setblock ~-2 ~2 ~-2 minecraft:oak_log[ axis=y] destroy
execute at @e[tag=only] run setblock ~-2 ~3 ~-2 minecraft:oak_log[ axis=y] destroy

execute at @e[tag=only] run setblock ~-2 ~ ~2 minecraft:oak_log[ axis=y] destroy
execute at @e[tag=only] run setblock ~-2 ~1 ~2 minecraft:oak_log[ axis=y] destroy
execute at @e[tag=only] run setblock ~-2 ~2 ~2 minecraft:oak_log[ axis=y] destroy
execute at @e[tag=only] run setblock ~-2 ~3 ~2 minecraft:oak_log[ axis=y] destroy

execute at @e[tag=only] run setblock ~2 ~ ~2 minecraft:oak_log[ axis=y] destroy
execute at @e[tag=only] run setblock ~2 ~1 ~2 minecraft:oak_log[ axis=y] destroy
execute at @e[tag=only] run setblock ~2 ~2 ~2 minecraft:oak_log[ axis=y] destroy
execute at @e[tag=only] run setblock ~2 ~3 ~2 minecraft:oak_log[ axis=y] destroy

execute at @e[tag=only] run setblock ~2 ~ ~-2 minecraft:oak_log[ axis=y] destroy
execute at @e[tag=only] run setblock ~2 ~1 ~-2 minecraft:oak_log[ axis=y] destroy
execute at @e[tag=only] run setblock ~2 ~2 ~-2 minecraft:oak_log[ axis=y] destroy
execute at @e[tag=only] run setblock ~2 ~3 ~-2 minecraft:oak_log[ axis=y] destroy

execute at @e[tag=only] run setblock ~ ~3 ~-2 minecraft:oak_wood[axis=y] destroy
execute at @e[tag=only] run setblock ~1 ~3 ~-2 minecraft:oak_wood[axis=y] destroy
execute at @e[tag=only] run setblock ~-1 ~3 ~-2 minecraft:oak_wood[axis=y] destroy
execute at @e[tag=only] run setblock ~ ~3 ~2 minecraft:oak_wood[axis=y] destroy
execute at @e[tag=only] run setblock ~1 ~3 ~2 minecraft:oak_wood[axis=y] destroy
execute at @e[tag=only] run setblock ~-1 ~3 ~2 minecraft:oak_wood[axis=y] destroy
execute at @e[tag=only] run setblock ~2 ~3 ~ minecraft:oak_wood[axis=x] destroy
execute at @e[tag=only] run setblock ~2 ~3 ~1 minecraft:oak_wood[axis=x] destroy
execute at @e[tag=only] run setblock ~2 ~3 ~-1 minecraft:oak_wood[axis=x] destroy
execute at @e[tag=only] run setblock ~-2 ~3 ~ minecraft:oak_wood[axis=x] destroy
execute at @e[tag=only] run setblock ~-2 ~3 ~1 minecraft:oak_wood[axis=x] destroy
execute at @e[tag=only] run setblock ~-2 ~3 ~-1 minecraft:oak_wood[axis=x] destroy

execute at @e[tag=only] run setblock ~ ~3 ~ glass destroy
execute at @e[tag=only] run setblock ~1 ~3 ~ glass destroy
execute at @e[tag=only] run setblock ~-1 ~3 ~ glass destroy
execute at @e[tag=only] run setblock ~ ~3 ~1 glass destroy
execute at @e[tag=only] run setblock ~ ~3 ~-1 glass destroy
execute at @e[tag=only] run setblock ~1 ~3 ~1 glass destroy
execute at @e[tag=only] run setblock ~-1 ~3 ~1 glass destroy
execute at @e[tag=only] run setblock ~-1 ~3 ~-1 glass destroy
execute at @e[tag=only] run setblock ~-1 ~3 ~1 glass destroy
execute at @e[tag=only] run setblock ~1 ~3 ~-1 glass destroy

execute at @e[tag=only] run setblock ~ ~1 ~-2 minecraft:oak_planks destroy
execute at @e[tag=only] run setblock ~1 ~1 ~-2 minecraft:oak_planks destroy
execute at @e[tag=only] run setblock ~-1 ~1 ~-2 minecraft:oak_planks destroy
execute at @e[tag=only] run setblock ~ ~1 ~2 minecraft:oak_door[facing=north,half=upper] destroy
execute at @e[tag=only] run setblock ~1 ~1 ~2 minecraft:oak_planks destroy
execute at @e[tag=only] run setblock ~-1 ~1 ~2 minecraft:oak_planks destroy
execute at @e[tag=only] run setblock ~2 ~1 ~ minecraft:glass_pane destroy
execute at @e[tag=only] run setblock ~2 ~1 ~1 minecraft:oak_planks destroy
execute at @e[tag=only] run setblock ~2 ~1 ~-1 minecraft:oak_planks destroy
execute at @e[tag=only] run setblock ~-2 ~1 ~ minecraft:glass_pane destroy
execute at @e[tag=only] run setblock ~-2 ~1 ~1 minecraft:oak_planks destroy
execute at @e[tag=only] run setblock ~-2 ~1 ~-1 minecraft:oak_planks destroy

execute at @e[tag=only] run setblock ~ ~ ~-2 minecraft:oak_planks destroy
execute at @e[tag=only] run setblock ~1 ~ ~-2 minecraft:oak_planks destroy
execute at @e[tag=only] run setblock ~-1 ~ ~-2 minecraft:oak_planks destroy
execute at @e[tag=only] run setblock ~ ~ ~2 minecraft:oak_door[facing=north,half=lower] destroy
execute at @e[tag=only] run setblock ~1 ~ ~2 minecraft:oak_planks destroy
execute at @e[tag=only] run setblock ~-1 ~ ~2 minecraft:oak_planks destroy
execute at @e[tag=only] run setblock ~2 ~ ~ minecraft:oak_planks destroy
execute at @e[tag=only] run setblock ~2 ~ ~1 minecraft:oak_planks destroy
execute at @e[tag=only] run setblock ~2 ~ ~-1 minecraft:oak_planks destroy
execute at @e[tag=only] run setblock ~-2 ~ ~ minecraft:oak_planks destroy
execute at @e[tag=only] run setblock ~-2 ~ ~1 minecraft:oak_planks destroy
execute at @e[tag=only] run setblock ~-2 ~ ~-1 minecraft:oak_planks destroy

execute at @e[tag=only] run setblock ~ ~2 ~-2 minecraft:oak_planks destroy
execute at @e[tag=only] run setblock ~1 ~2 ~-2 minecraft:oak_planks destroy
execute at @e[tag=only] run setblock ~-1 ~2 ~-2 minecraft:oak_planks destroy
execute at @e[tag=only] run setblock ~ ~2 ~2 minecraft:oak_planks destroy
execute at @e[tag=only] run setblock ~1 ~2 ~2 minecraft:oak_planks destroy
execute at @e[tag=only] run setblock ~-1 ~2 ~2 minecraft:oak_planks destroy
execute at @e[tag=only] run setblock ~2 ~2 ~ minecraft:oak_planks destroy
execute at @e[tag=only] run setblock ~2 ~2 ~1 minecraft:oak_planks destroy
execute at @e[tag=only] run setblock ~2 ~2 ~-1 minecraft:oak_planks destroy
execute at @e[tag=only] run setblock ~-2 ~2 ~ minecraft:oak_planks destroy
execute at @e[tag=only] run setblock ~-2 ~2 ~1 minecraft:oak_planks destroy
execute at @e[tag=only] run setblock ~-2 ~2 ~-1 minecraft:oak_planks destroy

execute at @e[tag=only] run setblock ~1 ~ ~-1 minecraft:white_bed[part=head] destroy
execute at @e[tag=only] run setblock ~1 ~ ~ minecraft:white_bed[part=foot] destroy
execute at @e[tag=only] run setblock ~-1 ~ ~ minecraft:furnace[facing=east] destroy
execute at @e[tag=only] run setblock ~-1 ~ ~-1 minecraft:crafting_table destroy
execute at @e[tag=only] run setblock ~-1 ~ ~1 minecraft:chest[type=single,facing=east]{LootTable:"inside_the_system_boring_aiko:aikos_chest_default"} destroy
execute at @e[tag=only] run setblock ~ ~ ~1 minecraft:oak_pressure_plate destroy
execute at @e[tag=only] run setblock ~-1 ~1 ~3 minecraft:oak_wall_sign[facing=south]{front_text:{color:"black",has_glowing_text:0b,messages:['{"text":""}','{"text":"Sweet house"}','{"text":""}','{"text":""}']},is_waxed:1b} destroy